2021-11-29 15:28:31,080  DEBUG    Соединение с базой данных открыто (main.py:31)
2021-11-29 15:28:31,080  INFO     Попытка очистки базы данных пользователей (main.py:178)
2021-11-29 15:28:31,083  WARNING  404 База данных питомцев пуста (crud.py:230)
2021-11-29 15:28:31,084  WARNING  404 База данных пользователей пуста (crud.py:226)
2021-11-29 15:28:31,084  DEBUG    Соединение с базой данных закрыто (main.py:36)
2021-11-29 15:28:31,087  DEBUG    Соединение с базой данных открыто (main.py:31)
2021-11-29 15:28:31,087  INFO     Попытка создать пользователя с email: "test_email_1" (main.py:42)
2021-11-29 15:28:31,091  INFO     Пользователь c email: "test_email_1" и id = 1 создан (crud.py:28)
2021-11-29 15:28:31,092  DEBUG    Соединение с базой данных закрыто (main.py:36)
2021-11-29 15:28:31,095  DEBUG    Соединение с базой данных открыто (main.py:31)
2021-11-29 15:28:31,095  INFO     Попытка создать пользователя с email: "test_email_1" (main.py:42)
2021-11-29 15:28:31,096  WARNING  400 Пользователь с таким email уже зарегистрирован (crud.py:204)
2021-11-29 15:28:31,096  DEBUG    Соединение с базой данных закрыто (main.py:36)
2021-11-29 15:28:31,098  DEBUG    Соединение с базой данных открыто (main.py:31)
2021-11-29 15:28:31,098  INFO     Попытка добавления питомца по кличке "test_title_1" пользователю с id = "1" (main.py:52)
2021-11-29 15:28:31,103  INFO     Питомец по кличке "test_title_1" добавлен пользователю с id = 1 (crud.py:44)
2021-11-29 15:28:31,103  DEBUG    Соединение с базой данных закрыто (main.py:36)
2021-11-29 15:28:31,106  DEBUG    Соединение с базой данных открыто (main.py:31)
2021-11-29 15:28:31,106  INFO     Попытка добавления питомца по кличке "test_title_1" пользователю с id = "1" (main.py:52)
2021-11-29 15:28:31,107  WARNING  400 У пользователя с id 1 уже есть питомец с такой кличкой и описанием (main.py:59)
2021-11-29 15:28:31,107  DEBUG    Соединение с базой данных закрыто (main.py:36)
2021-11-29 15:28:31,110  DEBUG    Соединение с базой данных открыто (main.py:31)
2021-11-29 15:28:31,110  INFO     Попытка добавления питомца по кличке "test_title" пользователю с id = "99" (main.py:52)
2021-11-29 15:28:31,110  WARNING  404 Пользователь с id 99 не найден (crud.py:226)
2021-11-29 15:28:31,111  DEBUG    Соединение с базой данных закрыто (main.py:36)
2021-11-29 15:28:31,113  DEBUG    Соединение с базой данных открыто (main.py:31)
2021-11-29 15:28:31,113  INFO     Попытка отобразить пользователя с id = 1 (main.py:77)
2021-11-29 15:28:31,113  INFO     Информация о пользователе с id = 1 предоставлена (main.py:80)
2021-11-29 15:28:31,114  DEBUG    Соединение с базой данных закрыто (main.py:36)
2021-11-29 15:28:31,116  DEBUG    Соединение с базой данных открыто (main.py:31)
2021-11-29 15:28:31,116  INFO     Попытка отобразить пользователя с id = 88 (main.py:77)
2021-11-29 15:28:31,117  WARNING  404 Пользователь с id 88 не найден (crud.py:226)
2021-11-29 15:28:31,117  DEBUG    Соединение с базой данных закрыто (main.py:36)
2021-11-29 15:28:31,119  DEBUG    Соединение с базой данных открыто (main.py:31)
2021-11-29 15:28:31,119  INFO     Попытка отобразить информацию о питомце по id хозяина = 1 и id животного = 77 (main.py:86)
2021-11-29 15:28:31,120  WARNING  404 Питомец по id хозяина = 1 и id животного = 77 не найден (crud.py:226)
2021-11-29 15:28:31,120  DEBUG    Соединение с базой данных закрыто (main.py:36)
2021-11-29 15:28:31,122  DEBUG    Соединение с базой данных открыто (main.py:31)
2021-11-29 15:28:31,122  INFO     Попытка отобразить информацию о питомце по id хозяина = 66 и id животного = 1 (main.py:86)
2021-11-29 15:28:31,123  WARNING  404 Питомец по id хозяина = 66 и id животного = 1 не найден (crud.py:226)
2021-11-29 15:28:31,123  DEBUG    Соединение с базой данных закрыто (main.py:36)
2021-11-29 15:28:31,125  DEBUG    Соединение с базой данных открыто (main.py:31)
2021-11-29 15:28:31,125  INFO     Попытка отобразить информацию о питомце по id хозяина = 1 и id животного = 1 (main.py:86)
2021-11-29 15:28:31,126  INFO     Информация о питомце по id хозяина = 1 и id животного = 1 предоставлена (main.py:89)
2021-11-29 15:28:31,126  DEBUG    Соединение с базой данных закрыто (main.py:36)
2021-11-29 15:28:31,128  DEBUG    Соединение с базой данных открыто (main.py:31)
2021-11-29 15:28:31,128  INFO     Попытка добавления питомца по кличке "test_title_2" пользователю с id = "1" (main.py:52)
2021-11-29 15:28:31,131  INFO     Питомец по кличке "test_title_2" добавлен пользователю с id = 1 (crud.py:44)
2021-11-29 15:28:31,132  DEBUG    Соединение с базой данных закрыто (main.py:36)
2021-11-29 15:28:31,134  DEBUG    Соединение с базой данных открыто (main.py:31)
2021-11-29 15:28:31,134  INFO     Попытка отобразить всех питомцев пользователя с id = 1 (main.py:95)
2021-11-29 15:28:31,134  INFO     Информация о питомцах пользователя с id = 1 предоставлена (main.py:99)
2021-11-29 15:28:31,135  DEBUG    Соединение с базой данных закрыто (main.py:36)
2021-11-29 15:28:31,137  DEBUG    Соединение с базой данных открыто (main.py:31)
2021-11-29 15:28:31,137  INFO     Попытка отобразить всех питомцев пользователя с id = 55 (main.py:95)
2021-11-29 15:28:31,137  WARNING  404 У пользователя с id = 55 нет питомцев или пользователя с таким id не существует (crud.py:226)
2021-11-29 15:28:31,137  DEBUG    Соединение с базой данных закрыто (main.py:36)
2021-11-29 15:28:31,139  DEBUG    Соединение с базой данных открыто (main.py:31)
2021-11-29 15:28:31,139  INFO     Попытка создать пользователя с email: "test_email_2" (main.py:42)
2021-11-29 15:28:31,142  INFO     Пользователь c email: "test_email_2" и id = 2 создан (crud.py:28)
2021-11-29 15:28:31,143  DEBUG    Соединение с базой данных закрыто (main.py:36)
2021-11-29 15:28:31,145  DEBUG    Соединение с базой данных открыто (main.py:31)
2021-11-29 15:28:31,145  INFO     Попытка добавления питомца по кличке "test_title_2" пользователю с id = "2" (main.py:52)
2021-11-29 15:28:31,148  INFO     Питомец по кличке "test_title_2" добавлен пользователю с id = 2 (crud.py:44)
2021-11-29 15:28:31,149  DEBUG    Соединение с базой данных закрыто (main.py:36)
2021-11-29 15:28:31,151  DEBUG    Соединение с базой данных открыто (main.py:31)
2021-11-29 15:28:31,151  INFO     Попытка отобразить всех питомцев в магазине (main.py:105)
2021-11-29 15:28:31,152  INFO     Информация о всех питомцах в магазине предоставлена (main.py:108)
2021-11-29 15:28:31,153  DEBUG    Соединение с базой данных закрыто (main.py:36)
2021-11-29 15:28:31,155  DEBUG    Соединение с базой данных открыто (main.py:31)
2021-11-29 15:28:31,155  INFO     Попытка изменить информацию о пользователе с id = 1 (main.py:115)
2021-11-29 15:28:31,158  INFO     Информация о пользователе с id = 1 изменена (crud.py:132)
2021-11-29 15:28:31,158  DEBUG    Соединение с базой данных закрыто (main.py:36)
2021-11-29 15:28:31,161  DEBUG    Соединение с базой данных открыто (main.py:31)
2021-11-29 15:28:31,161  INFO     Попытка изменить информацию о пользователе с id = 2 (main.py:115)
2021-11-29 15:28:31,162  WARNING  400 Пользователь с email: new_test_email_1 уже зарегистрирован (crud.py:204)
2021-11-29 15:28:31,162  DEBUG    Соединение с базой данных закрыто (main.py:36)
2021-11-29 15:28:31,164  DEBUG    Соединение с базой данных открыто (main.py:31)
2021-11-29 15:28:31,164  INFO     Попытка изменить информацию о пользователе с id = 33 (main.py:115)
2021-11-29 15:28:31,165  WARNING  404 Пользователь с id 33 не найден (crud.py:226)
2021-11-29 15:28:31,165  DEBUG    Соединение с базой данных закрыто (main.py:36)
2021-11-29 15:28:31,167  DEBUG    Соединение с базой данных открыто (main.py:31)
2021-11-29 15:28:31,167  INFO     Попытка изменить информацию о питомце по id хозяина = 77 и id животного = 1 (main.py:131)
2021-11-29 15:28:31,168  WARNING  404 Пользователь с id 77 не найден (crud.py:226)
2021-11-29 15:28:31,168  DEBUG    Соединение с базой данных закрыто (main.py:36)
2021-11-29 15:28:31,170  DEBUG    Соединение с базой данных открыто (main.py:31)
2021-11-29 15:28:31,170  INFO     Попытка изменить информацию о питомце по id хозяина = 1 и id животного = 77 (main.py:131)
2021-11-29 15:28:31,171  WARNING  404 Питомец с таким id у данного пользователя не найден (crud.py:226)
2021-11-29 15:28:31,171  DEBUG    Соединение с базой данных закрыто (main.py:36)
2021-11-29 15:28:31,173  DEBUG    Соединение с базой данных открыто (main.py:31)
2021-11-29 15:28:31,173  INFO     Попытка изменить информацию о питомце по id хозяина = 1 и id животного = 1 (main.py:131)
2021-11-29 15:28:31,178  INFO     Информация о питомце по id хозяина = 1 и id животного = 1 изменена (crud.py:151)
2021-11-29 15:28:31,178  DEBUG    Соединение с базой данных закрыто (main.py:36)
2021-11-29 15:28:31,180  DEBUG    Соединение с базой данных открыто (main.py:31)
2021-11-29 15:28:31,180  INFO     Попытка изменить информацию о питомце по id хозяина = 1 и id животного = 2 (main.py:131)
2021-11-29 15:28:31,182  WARNING  400 У пользователя уже есть питомец с такой кличкой и описанием (crud.py:204)
2021-11-29 15:28:31,182  DEBUG    Соединение с базой данных закрыто (main.py:36)
2021-11-29 15:28:31,184  DEBUG    Соединение с базой данных открыто (main.py:31)
2021-11-29 15:28:31,184  INFO     Попытка удаления все питомцев у пользователя с id = 1 (main.py:168)
2021-11-29 15:28:31,186  INFO     Питомец с id хозяина = 1 и id животного = 1 удален (crud.py:169)
2021-11-29 15:28:31,189  INFO     Питомец с id хозяина = 1 и id животного = 2 удален (crud.py:169)
2021-11-29 15:28:31,189  DEBUG    Соединение с базой данных закрыто (main.py:36)
2021-11-29 15:28:31,191  DEBUG    Соединение с базой данных открыто (main.py:31)
2021-11-29 15:28:31,191  INFO     Попытка удаления питомца по id хозяина = 2 и id животного = 3 (main.py:158)
2021-11-29 15:28:31,194  INFO     Питомец с id хозяина = 2 и id животного = 3 удален (crud.py:169)
2021-11-29 15:28:31,194  DEBUG    Соединение с базой данных закрыто (main.py:36)
2021-11-29 15:28:31,199  DEBUG    Соединение с базой данных открыто (main.py:31)
2021-11-29 15:28:31,200  INFO     Попытка удаления питомца по id хозяина = 1 и id животного = 77 (main.py:158)
2021-11-29 15:28:31,204  WARNING  404 Питомец с id хозяина = 1 и id животного = 77 не найден (crud.py:226)
2021-11-29 15:28:31,208  DEBUG    Соединение с базой данных закрыто (main.py:36)
2021-11-29 15:28:31,216  DEBUG    Соединение с базой данных открыто (main.py:31)
2021-11-29 15:28:31,216  INFO     Попытка удаления питомца по id хозяина = 77 и id животного = 1 (main.py:158)
2021-11-29 15:28:31,217  WARNING  404 Питомец с id хозяина = 77 и id животного = 1 не найден (crud.py:226)
2021-11-29 15:28:31,217  DEBUG    Соединение с базой данных закрыто (main.py:36)
2021-11-29 15:28:31,219  DEBUG    Соединение с базой данных открыто (main.py:31)
2021-11-29 15:28:31,219  INFO     Попытка удаления все питомцев у пользователя с id = 1 (main.py:168)
2021-11-29 15:28:31,220  WARNING  404 У пользователей с id = 1 нет питомцев или такого пользователя не существует (crud.py:226)
2021-11-29 15:28:31,220  DEBUG    Соединение с базой данных закрыто (main.py:36)
2021-11-29 15:28:31,223  DEBUG    Соединение с базой данных открыто (main.py:31)
2021-11-29 15:28:31,223  INFO     Попытка удаления все питомцев у пользователя с id = 55 (main.py:168)
2021-11-29 15:28:31,223  WARNING  404 У пользователей с id = 55 нет питомцев или такого пользователя не существует (crud.py:226)
2021-11-29 15:28:31,224  DEBUG    Соединение с базой данных закрыто (main.py:36)
2021-11-29 15:28:31,225  DEBUG    Соединение с базой данных открыто (main.py:31)
2021-11-29 15:28:31,225  INFO     Попытка удаления пользователя с id = 55 (main.py:147)
2021-11-29 15:28:31,226  WARNING  404 Пользователь с id = 55 не найден (crud.py:226)
2021-11-29 15:28:31,226  DEBUG    Соединение с базой данных закрыто (main.py:36)
2021-11-29 15:28:31,228  DEBUG    Соединение с базой данных открыто (main.py:31)
2021-11-29 15:28:31,229  INFO     Попытка удаления пользователя с id = 1 (main.py:147)
2021-11-29 15:28:31,231  INFO     Пользователь с id = 1 удален (crud.py:165)
2021-11-29 15:28:31,232  DEBUG    Соединение с базой данных закрыто (main.py:36)
2021-11-29 15:28:31,234  DEBUG    Соединение с базой данных открыто (main.py:31)
2021-11-29 15:28:31,234  INFO     Попытка очистки базы данных пользователей (main.py:178)
2021-11-29 15:28:31,234  WARNING  404 База данных питомцев пуста (crud.py:230)
2021-11-29 15:28:31,236  INFO     Пользователь с id = 2 удален (crud.py:165)
2021-11-29 15:28:31,236  DEBUG    Соединение с базой данных закрыто (main.py:36)
2021-11-29 15:28:31,239  DEBUG    Соединение с базой данных открыто (main.py:31)
2021-11-29 15:28:31,239  INFO     Попытка очистки базы данных пользователей (main.py:178)
2021-11-29 15:28:31,239  WARNING  404 База данных питомцев пуста (crud.py:230)
2021-11-29 15:28:31,239  WARNING  404 База данных пользователей пуста (crud.py:226)
2021-11-29 15:28:31,240  DEBUG    Соединение с базой данных закрыто (main.py:36)
2021-11-29 15:28:31,241  DEBUG    Соединение с базой данных открыто (main.py:31)
2021-11-29 15:28:31,242  INFO     Попытка создать пользователя с email: "test_email_3" (main.py:42)
2021-11-29 15:28:31,245  INFO     Пользователь c email: "test_email_3" и id = 1 создан (crud.py:28)
2021-11-29 15:28:31,245  DEBUG    Соединение с базой данных закрыто (main.py:36)
2021-11-29 15:28:31,248  DEBUG    Соединение с базой данных открыто (main.py:31)
2021-11-29 15:28:31,248  INFO     Попытка отобразить всех питомцев в магазине (main.py:105)
2021-11-29 15:28:31,248  WARNING  404 База данных питомцев пуста (crud.py:226)
2021-11-29 15:28:31,248  DEBUG    Соединение с базой данных закрыто (main.py:36)
2021-11-29 15:28:31,250  DEBUG    Соединение с базой данных открыто (main.py:31)
2021-11-29 15:28:31,250  INFO     Попытка очистки базы данных пользователей (main.py:178)
2021-11-29 15:28:31,251  WARNING  404 База данных питомцев пуста (crud.py:230)
2021-11-29 15:28:31,253  INFO     Пользователь с id = 1 удален (crud.py:165)
2021-11-29 15:28:31,253  DEBUG    Соединение с базой данных закрыто (main.py:36)
